<?xml version="1.0" encoding="utf-8"?>
<robot
  name="robot_urdf">
  <link
    name="base_link">
    <inertial>
      <origin
        xyz="0.043983 0.025052 0.088842"
        rpy="0 0 0" />
      <mass
        value="0.56283" />
      <inertia
        ixx="0.00067975"
        ixy="-5.3938E-21"
        ixz="0"
        iyy="0.0008459"
        iyz="-4.7116E-20"
        izz="0.00067975" />
    </inertial>
    <visual>
      <origin
        xyz="0 0 0"
        rpy="0 0 0" />
      <geometry>
        <mesh
          filename="package://robot_urdf/meshes/base_link.STL" />
      </geometry>
      <material
        name="">
        <color
          rgba="0.79216 0.81961 0.93333 1" />
      </material>
    </visual>
    <collision>
      <origin
        xyz="0 0 0"
        rpy="0 0 0" />
      <geometry>
        <mesh
          filename="package://robot_urdf/meshes/base_link.STL" />
      </geometry>
    </collision>
  </link>
  <link
    name="first_arm">
    <inertial>
      <origin
        xyz="-0.12572 0.03143 -0.00077706"
        rpy="0 0 0" />
      <mass
        value="0.48857" />
      <inertia
        ixx="0.0003187"
        ixy="0.00023336"
        ixz="-1.7965E-05"
        iyy="0.0030665"
        iyz="1.4423E-06"
        izz="0.0032251" />
    </inertial>
    <visual>
      <origin
        xyz="0 0 0"
        rpy="0 0 0" />
      <geometry>
        <mesh
          filename="package://robot_urdf/meshes/first_arm.STL" />
      </geometry>
      <material
        name="">
        <color
          rgba="0.79216 0.81961 0.93333 1" />
      </material>
    </visual>
    <collision>
      <origin
        xyz="0 0 0"
        rpy="0 0 0" />
      <geometry>
        <mesh
          filename="package://robot_urdf/meshes/first_arm.STL" />
      </geometry>
    </collision>
  </link>
  <joint
    name="joint1"
    type="continuous">
    <origin
      xyz="0.043983 -0.088842 0.04447"
      rpy="1.5708 0 1.9294" />
    <parent
      link="base_link" />
    <child
      link="first_arm" />
    <axis
      xyz="0 1 0" />
  </joint>
  <link
    name="second_arm">
    <inertial>
      <origin
        xyz="-0.12572 0.03143 -0.00077706"
        rpy="0 0 0" />
      <mass
        value="0.48857" />
      <inertia
        ixx="0.0003187"
        ixy="0.00023336"
        ixz="-1.7963E-05"
        iyy="0.0030664"
        iyz="1.4415E-06"
        izz="0.0032251" />
    </inertial>
    <visual>
      <origin
        xyz="0 0 0"
        rpy="0 0 0" />
      <geometry>
        <mesh
          filename="package://robot_urdf/meshes/second_arm.STL" />
      </geometry>
      <material
        name="">
        <color
          rgba="0.79216 0.81961 0.93333 1" />
      </material>
    </visual>
    <collision>
      <origin
        xyz="0 0 0"
        rpy="0 0 0" />
      <geometry>
        <mesh
          filename="package://robot_urdf/meshes/second_arm.STL" />
      </geometry>
    </collision>
  </link>
  <joint
    name="joint2"
    type="continuous">
    <origin
      xyz="-0.2 0.05 -0.0012362"
      rpy="0 -0.31265 0" />
    <parent
      link="first_arm" />
    <child
      link="second_arm" />
    <axis
      xyz="0 1 0" />
  </joint>
</robot>