<?xml version="1.0"?>
<robot xmlns:xacro="http://www.ros.org/wiki/xacro" name="six_dof_robot">

  <link name="base_link">
    <inertial>
      <mass value="1.0"/>
      <origin rpy="0 0 0" xyz="0 0 0"/>
      <inertia ixx="0.005" ixy="0" ixz="0" iyy="0.005" iyz="0" izz="0.005"/>
    </inertial>
    <visual>
      <origin xyz="0 0 0" rpy="0 0 0"/>
      <geometry>
        <box size="0.2 0.2 0.2"/>
      </geometry>
      <material name="blue">
        <color rgba="0.0 0.0 1.0 1.0"/>
      </material>
    </visual>
  </link>

  <joint name="base_to_arm1" type="revolute">
    <parent link="base_link"/>
    <child link="arm1_link"/>
    <axis xyz="0 1 0"/>
    <limit effort="1000" lower="-1.57" upper="1.57" velocity="2.0"/>
    <origin rpy="0 0 0" xyz="0 0 0.1"/>
  </joint>

  <link name="arm1_link">
    <inertial>
      <mass value="1.0"/>
      <origin rpy="0 0 0" xyz="0.1 0 0"/>
      <inertia ixx="0.005" ixy="0" ixz="0" iyy="0.005" iyz="0" izz="0.005"/>
    </inertial>
    <visual>
      <origin xyz="0 0 0" rpy="0 0 0"/>
      <geometry>
        <box size="0.2 0.2 0.2"/>
      </geometry>
      <material name="red">
        <color rgba="1.0 0.0 0.0 1.0"/>
      </material>
    </visual>
  </link>

  <joint name="arm1_to_arm2" type="revolute">
    <parent link="arm1_link"/>
    <child link="arm2_link"/>
    <axis xyz="0 1 0"/>
    <limit effort="1000" lower="-1.57" upper="1.57" velocity="2.0"/>
    <origin rpy="0 0 0" xyz="0.2 0 0"/>
  </joint>

  <link name="arm2_link">
    <inertial>
      <mass value="1.0"/>
      <origin rpy="0 0 0" xyz="0.1 0 0"/>
      <inertia ixx="0.005" ixy="0" ixz="0" iyy="0.005" iyz="0" izz="0.005"/>
    </inertial>
    <visual>
      <origin xyz="0 0 0" rpy="0 0 0"/>
      <geometry>
        <box size="0.2 0.2 0.2"/>
      </geometry>
      <material name="green">
        <color rgba="0.0 1.0 0.0 1.0"/>
      </material>
      </visual>
  </link>
    </robot>